Workbook
Name Barang: 'Kode Data'!$B$3:$C$23
Name Ekspedisi: 'Kode Data'!$E$9:$F$13
Name Kategori: 'Kode Data'!$E$3:$G$6

Sheet Dashboard

Sheet Kode Data
B2: Kode Barang | C2: Nama Barang | E2: Kode Kategori | F2: Kategori Barang
B3: RM001 | C3: Gandum Hard Wheat | E3: RM | F3: Raw Material | G3: Bahan Baku
B4: RM002 | C4: Gandum Soft Wheat | E4: AD | F4: Additive | G4: Bahan Tambahan
B5: RM003 | C5: Gandum Durum | E5: PK | F5: Packaging | G5: Kemasan
B6: RM004 | C6: Bran Gandum | E6: FG | F6: Finished Goods | G6: Produk
B7: RM005 | C7: Germ Gandum
B8: AD001 | C8: Enzim Baking | E8: Nama Ekspedisi | F8: Kode Ekspedisi
B9: AD002 | C9: Vitamin Fortifikasi | E9: J&T | F9: JT
B10: AD003 | C10: Tepung Premix | E10: Pos Indonesia | F10: PI
B11: AD004 | C11: Improver Tepung | E11: SiCepat | F11: SC
B12: AD005 | C12: Calcium Propionate | E12: TIKI | F12: TI
B13: PK001 | C13: Karung Kemasan 25 Kg | E13: JNE | F13: JN
B14: PK002 | C14: Plastik Kemasan 1 Kg
B15: PK003 | C15: Plastik Kemasan 500 gr
B16: PK004 | C16: Karton Box
B17: PK005 | C17: Label Produk
B18: PK006 | C18: Pallet Kayu
B19: FG001 | C19: Tepung Terigu Protein Tinggi
B20: FG002 | C20: Tepung Terigu Serbaguna
B21: FG003 | C21: Tepung Terigu Protein Rendah
B22: FG004 | C22: Tepung Terigu Khusus Roti
B23: FG005 | C23: Tepung Terigu Khusus Kue

Sheet Master Data
A1: Tanggal | B1: Kode Barang | C1: Nama Barang | D1: Kategori | E1: Supllier | F1: Barang Masuk | G1: Barang Keluar | H1: Stok Awal | I1: Stok Akhir | J1: Satuan | K1: Keterangan | M1: Kode Barang | N1: Nama Barang | O1: Total Stok Awal | P1: Total Stok Akhir | Q1: Stok Akhir
A2: 45658 | B2: FG003 | C2: =VLOOKUP(B2,'Kode Data'!$B$3:$C$23,2,0) -> Tepung Terigu Protein Rendah | D2: =VLOOKUP(LEFT(B2,2),'Kode Data'!$E$3:$G$6,3,0) -> Produk | E2: PT Agro Makmur | F2: 500 | G2: 0 | H2: 1000 | I2: 1500 | J2: Pcs | K2: Hasil Produksi | M2: RM001 | N2: =VLOOKUP(M2,Barang,2,0) -> Gandum Hard Wheat | O2: =SUMIF($B$2:$B$949,M2,$F$2:$F$949)+1000 -> 13950 | P2: =SUMIF($B$2:$B$949,M2,$G$2:$G$949) -> 10250 | Q2: =O2-P2 -> 3700
A3: 45658 | B3: FG004 | C3: =VLOOKUP(B3,'Kode Data'!$B$3:$C$23,2,0) -> Tepung Terigu Khusus Roti | D3: =VLOOKUP(LEFT(B3,2),'Kode Data'!$E$3:$G$6,3,0) -> Produk | E3: PT Pangan Jaya | F3: 500 | G3: 0 | H3: 1000 | I3: 1500 | J3: Pcs | K3: Hasil Produksi | M3: RM002 | N3: =VLOOKUP(M3,Barang,2,0) -> Gandum Soft Wheat | O3: =SUMIF($B$2:$B$949,M3,$F$2:$F$949)+1000 -> 10500 | P3: =SUMIF($B$2:$B$949,M3,$G$2:$G$949) -> 7700 | Q3: =O3-P3 -> 2800
A4: 45658 | B4: FG005 | C4: =VLOOKUP(B4,'Kode Data'!$B$3:$C$23,2,0) -> Tepung Terigu Khusus Kue | D4: =VLOOKUP(LEFT(B4,2),'Kode Data'!$E$3:$G$6,3,0) -> Produk | E4: PT Baker Indonesia | F4: 500 | G4: 0 | H4: 1000 | I4: 1500 | J4: Pcs | K4: Hasil Produksi | M4: RM003 | N4: =VLOOKUP(M4,Barang,2,0) -> Gandum Durum | O4: =SUMIF($B$2:$B$949,M4,$F$2:$F$949)+1000 -> 8190 | P4: =SUMIF($B$2:$B$949,M4,$G$2:$G$949) -> 6550 | Q4: =O4-P4 -> 1640
A5: 45658 | B5: PK001 | C5: =VLOOKUP(B5,'Kode Data'!$B$3:$C$23,2,0) -> Karung Kemasan 25 Kg | D5: =VLOOKUP(LEFT(B5,2),'Kode Data'!$E$3:$G$6,3,0) -> Kemasan | E5: PT Kemasan Jaya | F5: 500 | G5: 0 | H5: 1000 | I5: 1500 | J5: Pcs | K5: Restock Kemasan | M5: RM004 | N5: =VLOOKUP(M5,Barang,2,0) -> Bran Gandum | O5: =SUMIF($B$2:$B$949,M5,$F$2:$F$949)+500 -> 9300 | P5: =SUMIF($B$2:$B$949,M5,$G$2:$G$949) -> 6400 | Q5: =O5-P5 -> 2900
A6: 45658 | B6: PK002 | C6: =VLOOKUP(B6,'Kode Data'!$B$3:$C$23,2,0) -> Plastik Kemasan 1 Kg | D6: =VLOOKUP(LEFT(B6,2),'Kode Data'!$E$3:$G$6,3,0) -> Kemasan | E6: PT Plastik Nusantara | F6: 1000 | G6: 0 | H6: 5000 | I6: 6000 | J6: Pcs | K6: Restock Kemasan | M6: RM005 | N6: =VLOOKUP(M6,Barang,2,0) -> Germ Gandum | O6: =SUMIF($B$2:$B$949,M6,$F$2:$F$949)+500 -> 7060 | P6: =SUMIF($B$2:$B$949,M6,$G$2:$G$949) -> 4650 | Q6: =O6-P6 -> 2410
A7: 45658 | B7: RM005 | C7: =VLOOKUP(B7,'Kode Data'!$B$3:$C$23,2,0) -> Germ Gandum | D7: =VLOOKUP(LEFT(B7,2),'Kode Data'!$E$3:$G$6,3,0) -> Bahan Baku | E7: PT Agro Makmur | F7: 300 | G7: 0 | H7: 500 | I7: 800 | J7: Kg | K7: Restock Bahan Baku | M7: AD001 | N7: =VLOOKUP(M7,Barang,2,0) -> Enzim Baking | O7: =SUMIF($B$2:$B$949,M7,$F$2:$F$949)+200 -> 2685 | P7: =SUMIF($B$2:$B$949,M7,$G$2:$G$949) -> 2405 | Q7: =O7-P7 -> 280
A8: 45659 | B8: FG003 | C8: =VLOOKUP(B8,'Kode Data'!$B$3:$C$23,2,0) -> Tepung Terigu Protein Rendah | D8: =VLOOKUP(LEFT(B8,2),'Kode Data'!$E$3:$G$6,3,0) -> Produk | E8: PT Sumber Pangan | F8: 0 | G8: 400 | H8: 1500 | I8: 1100 | J8: Pcs | K8: Distribusi ke Customer | M8: AD002 | N8: =VLOOKUP(M8,Barang,2,0) -> Vitamin Fortifikasi | O8: =SUMIF($B$2:$B$949,M8,$F$2:$F$949)+200 -> 3140 | P8: =SUMIF($B$2:$B$949,M8,$G$2:$G$949) -> 2200 | Q8: =O8-P8 -> 940
A9: 45659 | B9: FG004 | C9: =VLOOKUP(B9,'Kode Data'!$B$3:$C$23,2,0) -> Tepung Terigu Khusus Roti | D9: =VLOOKUP(LEFT(B9,2),'Kode Data'!$E$3:$G$6,3,0) -> Produk | E9: PT Sumber Pangan | F9: 0 | G9: 400 | H9: 1500 | I9: 1100 | J9: Pcs | K9: Distribusi ke Customer | M9: AD003 | N9: =VLOOKUP(M9,Barang,2,0) -> Tepung Premix | O9: =SUMIF($B$2:$B$949,M9,$F$2:$F$949)+500 -> 5070 | P9: =SUMIF($B$2:$B$949,M9,$G$2:$G$949) -> 4190 | Q9: =O9-P9 -> 880
A10: 45659 | B10: FG005 | C10: =VLOOKUP(B10,'Kode Data'!$B$3:$C$23,2,0) -> Tepung Terigu Khusus Kue | D10: =VLOOKUP(LEFT(B10,2),'Kode Data'!$E$3:$G$6,3,0) -> Produk | E10: PT Mega Flour | F10: 0 | G10: 300 | H10: 1500 | I10: 1200 | J10: Pcs | K10: Distribusi ke Customer | M10: AD004 | N10: =VLOOKUP(M10,Barang,2,0) -> Improver Tepung | O10: =SUMIF($B$2:$B$949,M10,$F$2:$F$949)+200 -> 3730 | P10: =SUMIF($B$2:$B$949,M10,$G$2:$G$949) -> 3320 | Q10: =O10-P10 -> 410
A11: 45659 | B11: PK002 | C11: =VLOOKUP(B11,'Kode Data'!$B$3:$C$23,2,0) -> Plastik Kemasan 1 Kg | D11: =VLOOKUP(LEFT(B11,2),'Kode Data'!$E$3:$G$6,3,0) -> Kemasan | E11: PT Plastik Sejahtera | F11: 0 | G11: 300 | H11: 6000 | I11: 5700 | J11: Pcs | K11: Digunakan Packaging | M11: AD005 | N11: =VLOOKUP(M11,Barang,2,0) -> Calcium Propionate | O11: =SUMIF($B$2:$B$949,M11,$F$2:$F$949)+200 -> 1450 | P11: =SUMIF($B$2:$B$949,M11,$G$2:$G$949) -> 720 | Q11: =O11-P11 -> 730
A12: 45659 | B12: PK006 | C12: =VLOOKUP(B12,'Kode Data'!$B$3:$C$23,2,0) -> Pallet Kayu | D12: =VLOOKUP(LEFT(B12,2),'Kode Data'!$E$3:$G$6,3,0) -> Kemasan | E12: PT Pallet Nusantara | F12: 50 | G12: 0 | H12: 100 | I12: 150 | J12: Pcs | K12: Restock Kemasan | M12: PK001 | N12: =VLOOKUP(M12,Barang,2,0) -> Karung Kemasan 25 Kg | O12: =SUMIF($B$2:$B$949,M12,$F$2:$F$949)+1000 -> 10850 | P12: =SUMIF($B$2:$B$949,M12,$G$2:$G$949) -> 5330 | Q12: =O12-P12 -> 5520
A13: 45660 | B13: AD005 | C13: =VLOOKUP(B13,'Kode Data'!$B$3:$C$23,2,0) -> Calcium Propionate | D13: =VLOOKUP(LEFT(B13,2),'Kode Data'!$E$3:$G$6,3,0) -> Bahan Tambahan | E13: PT Nutri Pangan | F13: 50 | G13: 0 | H13: 200 | I13: 250 | J13: Kg | K13: Restock Bahan Tambahan | M13: PK002 | N13: =VLOOKUP(M13,Barang,2,0) -> Plastik Kemasan 1 Kg | O13: =SUMIF($B$2:$B$949,M13,$F$2:$F$949)+5000 -> 29000 | P13: =SUMIF($B$2:$B$949,M13,$G$2:$G$949) -> 11900 | Q13: =O13-P13 -> 17100
A14: 45660 | B14: FG005 | C14: =VLOOKUP(B14,'Kode Data'!$B$3:$C$23,2,0) -> Tepung Terigu Khusus Kue | D14: =VLOOKUP(LEFT(B14,2),'Kode Data'!$E$3:$G$6,3,0) -> Produk | E14: PT Sumber Pangan | F14: 600 | G14: 0 | H14: 1200 | I14: 1800 | J14: Pcs | K14: Hasil Produksi | M14: PK003 | N14: =VLOOKUP(M14,Barang,2,0) -> Plastik Kemasan 500 gr | O14: =SUMIF($B$2:$B$949,M14,$F$2:$F$949)+5000 -> 12700 | P14: =SUMIF($B$2:$B$949,M14,$G$2:$G$949) -> 3350 | Q14: =O14-P14 -> 9350
A15: 45660 | B15: PK001 | C15: =VLOOKUP(B15,'Kode Data'!$B$3:$C$23,2,0) -> Karung Kemasan 25 Kg | D15: =VLOOKUP(LEFT(B15,2),'Kode Data'!$E$3:$G$6,3,0) -> Kemasan | E15: PT Plastik Nusantara | F15: 0 | G15: 200 | H15: 1500 | I15: 1300 | J15: Pcs | K15: Digunakan Packaging | M15: PK004 | N15: =VLOOKUP(M15,Barang,2,0) -> Karton Box | O15: =SUMIF($B$2:$B$949,M15,$F$2:$F$949)+5000 -> 26200 | P15: =SUMIF($B$2:$B$949,M15,$G$2:$G$949) -> 11750 | Q15: =O15-P15 -> 14450
A16: 45660 | B16: PK004 | C16: =VLOOKUP(B16,'Kode Data'!$B$3:$C$23,2,0) -> Karton Box | D16: =VLOOKUP(LEFT(B16,2),'Kode Data'!$E$3:$G$6,3,0) -> Kemasan | E16: PT Karton Indonesia | F16: 1000 | G16: 0 | H16: 5000 | I16: 6000 | J16: Pcs | K16: Restock Kemasan | M16: PK005 | N16: =VLOOKUP(M16,Barang,2,0) -> Label Produk | O16: =SUMIF($B$2:$B$949,M16,$F$2:$F$949)+1000 -> 11800 | P16: =SUMIF($B$2:$B$949,M16,$G$2:$G$949) -> 9600 | Q16: =O16-P16 -> 2200
A17: 45660 | B17: RM002 | C17: =VLOOKUP(B17,'Kode Data'!$B$3:$C$23,2,0) -> Gandum Soft Wheat | D17: =VLOOKUP(LEFT(B17,2),'Kode Data'!$E$3:$G$6,3,0) -> Bahan Baku | E17: PT Pangan Nusantara | F17: 500 | G17: 0 | H17: 1000 | I17: 1500 | J17: Kg | K17: Restock Bahan Baku | M17: PK006 | N17: =VLOOKUP(M17,Barang,2,0) -> Pallet Kayu | O17: =SUMIF($B$2:$B$949,M17,$F$2:$F$949)+100 -> 1380 | P17: =SUMIF($B$2:$B$949,M17,$G$2:$G$949) -> 1030 | Q17: =O17-P17 -> 350
A18: 45661 | B18: FG003 | C18: =VLOOKUP(B18,'Kode Data'!$B$3:$C$23,2,0) -> Tepung Terigu Protein Rendah | D18: =VLOOKUP(LEFT(B18,2),'Kode Data'!$E$3:$G$6,3,0) -> Produk | E18: PT Pangan Jaya | F18: 600 | G18: 0 | H18: 1100 | I18: 1700 | J18: Pcs | K18: Hasil Produksi | M18: FG001 | N18: =VLOOKUP(M18,Barang,2,0) -> Tepung Terigu Protein Tinggi | O18: =SUMIF($B$2:$B$949,M18,$F$2:$F$949)+300 -> 15700 | P18: =SUMIF($B$2:$B$949,M18,$G$2:$G$949) -> 13600 | Q18: =O18-P18 -> 2100
A19: 45661 | B19: FG004 | C19: =VLOOKUP(B19,'Kode Data'!$B$3:$C$23,2,0) -> Tepung Terigu Khusus Roti | D19: =VLOOKUP(LEFT(B19,2),'Kode Data'!$E$3:$G$6,3,0) -> Produk | E19: PT Agro Makmur | F19: 600 | G19: 0 | H19: 1100 | I19: 1700 | J19: Pcs | K19: Hasil Produksi | M19: FG002 | N19: =VLOOKUP(M19,Barang,2,0) -> Tepung Terigu Serbaguna | O19: =SUMIF($B$2:$B$949,M19,$F$2:$F$949)+300 -> 17700 | P19: =SUMIF($B$2:$B$949,M19,$G$2:$G$949) -> 14600 | Q19: =O19-P19 -> 3100
A20: 45661 | B20: PK002 | C20: =VLOOKUP(B20,'Kode Data'!$B$3:$C$23,2,0) -> Plastik Kemasan 1 Kg | D20: =VLOOKUP(LEFT(B20,2),'Kode Data'!$E$3:$G$6,3,0) -> Kemasan | E20: PT Plastik Indo | F20: 1200 | G20: 0 | H20: 5700 | I20: 6900 | J20: Pcs | K20: Restock Kemasan | M20: FG003 | N20: =VLOOKUP(M20,Barang,2,0) -> Tepung Terigu Protein Rendah | O20: =SUMIF($B$2:$B$949,M20,$F$2:$F$949)+1000 -> 15400 | P20: =SUMIF($B$2:$B$949,M20,$G$2:$G$949) -> 12600 | Q20: =O20-P20 -> 2800
A21: 45661 | B21: RM001 | C21: =VLOOKUP(B21,'Kode Data'!$B$3:$C$23,2,0) -> Gandum Hard Wheat | D21: =VLOOKUP(LEFT(B21,2),'Kode Data'!$E$3:$G$6,3,0) -> Bahan Baku | E21: PT Sumber Pangan | F21: 500 | G21: 0 | H21: 1000 | I21: 1500 | J21: Kg | K21: Restock Bahan Baku | M21: FG004 | N21: =VLOOKUP(M21,Barang,2,0) -> Tepung Terigu Khusus Roti | O21: =SUMIF($B$2:$B$949,M21,$F$2:$F$949)+1000 -> 5750 | P21: =SUMIF($B$2:$B$949,M21,$G$2:$G$949) -> 3900 | Q21: =O21-P21 -> 1850
A22: 45662 | B22: AD001 | C22: =VLOOKUP(B22,'Kode Data'!$B$3:$C$23,2,0) -> Enzim Baking | D22: =VLOOKUP(LEFT(B22,2),'Kode Data'!$E$3:$G$6,3,0) -> Bahan Tambahan | E22: PT Bio Enzim Nusantara | F22: 120 | G22: 0 | H22: 200 | I22: 320 | J22: Kg | K22: Restock Bahan Tambahan | M22: FG005 | N22: =VLOOKUP(M22,Barang,2,0) -> Tepung Terigu Khusus Kue | O22: =SUMIF($B$2:$B$949,M22,$F$2:$F$949)+1000 -> 14600 | P22: =SUMIF($B$2:$B$949,M22,$G$2:$G$949) -> 10850 | Q22: =O22-P22 -> 3750
A23: 45662 | B23: AD002 | C23: =VLOOKUP(B23,'Kode Data'!$B$3:$C$23,2,0) -> Vitamin Fortifikasi | D23: =VLOOKUP(LEFT(B23,2),'Kode Data'!$E$3:$G$6,3,0) -> Bahan Tambahan | E23: PT Nutri Indo | F23: 120 | G23: 0 | H23: 200 | I23: 320 | J23: Kg | K23: Restock Bahan Tambahan | M23: Total | O23: =SUM(O2:O22) -> 226155 | P23: =SUM(P2:P22) -> 146895 | Q23: =SUM(Q2:Q22) -> 79260
A24: 45662 | B24: AD003 | C24: =VLOOKUP(B24,'Kode Data'!$B$3:$C$23,2,0) -> Tepung Premix | D24: =VLOOKUP(LEFT(B24,2),'Kode Data'!$E$3:$G$6,3,0) -> Bahan Tambahan | E24: PT Pangan Jaya | F24: 200 | G24: 0 | H24: 500 | I24: 700 | J24: Kg | K24: Restock Bahan Tambahan
A25: 45662 | B25: AD004 | C25: =VLOOKUP(B25,'Kode Data'!$B$3:$C$23,2,0) -> Improver Tepung | D25: =VLOOKUP(LEFT(B25,2),'Kode Data'!$E$3:$G$6,3,0) -> Bahan Tambahan | E25: PT Nutri Pangan | F25: 120 | G25: 0 | H25: 200 | I25: 320 | J25: Kg | K25: Restock Bahan Tambahan
A26: 45662 | B26: FG001 | C26: =VLOOKUP(B26,'Kode Data'!$B$3:$C$23,2,0) -> Tepung Terigu Protein Tinggi | D26: =VLOOKUP(LEFT(B26,2),'Kode Data'!$E$3:$G$6,3,0) -> Produk | E26: PT Distributor A | F26: 600 | G26: 0 | H26: 300 | I26: 900 | J26: Pcs | K26: Hasil Produksi
A27: 45662 | B27: FG002 | C27: =VLOOKUP(B27,'Kode Data'!$B$3:$C$23,2,0) -> Tepung Terigu Serbaguna | D27: =VLOOKUP(LEFT(B27,2),'Kode Data'!$E$3:$G$6,3,0) -> Produk | E27: PT Pangan Jaya | F27: 500 | G27: 0 | H27: 300 | I27: 800 | J27: Pcs | K27: Hasil Produksi
A28: 45662 | B28: FG003 | C28: =VLOOKUP(B28,'Kode Data'!$B$3:$C$23,2,0) -> Tepung Terigu Protein Rendah | D28: =VLOOKUP(LEFT(B28,2),'Kode Data'!$E$3:$G$6,3,0) -> Produk | E28: PT Agro Makmur | F28: 0 | G28: 500 | H28: 1700 | I28: 1200 | J28: Pcs | K28: Distribusi ke Customer
A29: 45662 | B29: FG005 | C29: =VLOOKUP(B29,'Kode Data'!$B$3:$C$23,2,0) -> Tepung Terigu Khusus Kue | D29: =VLOOKUP(LEFT(B29,2),'Kode Data'!$E$3:$G$6,3,0) -> Produk | E29: PT Baker Indonesia | F29: 0 | G29: 400 | H29: 1800 | I29: 1400 | J29: Pcs | K29: Distribusi ke Customer
A30: 45662 | B30: PK001 | C30: =VLOOKUP(B30,'Kode Data'!$B$3:$C$23,2,0) -> Karung Kemasan 25 Kg | D30: =VLOOKUP(LEFT(B30,2),'Kode Data'!$E$3:$G$6,3,0) -> Kemasan | E30: PT Karton Indonesia | F30: 300 | G30: 0 | H30: 1300 | I30: 1600 | J30: Pcs | K30: Restock Kemasan
A31: 45662 | B31: RM003 | C31: =VLOOKUP(B31,'Kode Data'!$B$3:$C$23,2,0) -> Gandum Durum | D31: =VLOOKUP(LEFT(B31,2),'Kode Data'!$E$3:$G$6,3,0) -> Bahan Baku | E31: PT Sumber Pangan | F31: 400 | G31: 0 | H31: 1000 | I31: 1400 | J31: Kg | K31: Restock Bahan Baku
A32: 45663 | B32: PK002 | C32: =VLOOKUP(B32,'Kode Data'!$B$3:$C$23,2,0) -> Plastik Kemasan 1 Kg | D32: =VLOOKUP(LEFT(B32,2),'Kode Data'!$E$3:$G$6,3,0) -> Kemasan | E32: PT Plastik Nusantara | F32: 0 | G32: 400 | H32: 6900 | I32: 6500 | J32: Pcs | K32: Digunakan Packaging
A33: 45663 | B33: PK005 | C33: =VLOOKUP(B33,'Kode Data'!$B$3:$C$23,2,0) -> Label Produk | D33: =VLOOKUP(LEFT(B33,2),'Kode Data'!$E$3:$G$6,3,0) -> Kemasan | E33: PT Labelindo | F33: 500 | G33: 0 | H33: 1000 | I33: 1500 | J33: Pcs | K33: Restock Kemasan
A34: 45664 | B34: FG003 | C34: =VLOOKUP(B34,'Kode Data'!$B$3:$C$23,2,0) -> Tepung Terigu Protein Rendah | D34: =VLOOKUP(LEFT(B34,2),'Kode Data'!$E$3:$G$6,3,0) -> Produk | E34: PT Sumber Pangan | F34: 400 | G34: 0 | H34: 1200 | I34: 1600 | J34: Pcs | K34: Hasil Produksi
A35: 45664 | B35: FG005 | C35: =VLOOKUP(B35,'Kode Data'!$B$3:$C$23,2,0) -> Tepung Terigu Khusus Kue | D35: =VLOOKUP(LEFT(B35,2),'Kode Data'!$E$3:$G$6,3,0) -> Produk | E35: PT Mega Flour | F35: 550 | G35: 0 | H35: 1400 | I35: 1950 | J35: Pcs | K35: Hasil Produksi
... A949: 46022 | B949: RM003 | C949: =VLOOKUP(B949,'Kode Data'!$B$3:$C$23,2,0) -> Gandum Durum | D949: =VLOOKUP(LEFT(B949,2),'Kode Data'!$E$3:$G$6,3,0) -> Bahan Baku | E949: PT Agro Makmur | F949: 0 | G949: 260 | H949: 1900 | I949: 1640 | J949: Kg | K949: Digunakan Produksi

Sheet Tracking Distribusi Barang
A1: Tanggal | B1: No Delivery Order | C1: Kode Barang | D1: Nama Barang | E1: Customer | F1: Kota Tujuan | G1: Barang Keluar | H1: Satuan | I1: Ekspedisi | J1: No. Resi | K1: Plat Nomer | L1: Status | M1: Tanggal Diterima | N1: Lead Time | O1: Keterlambatan
A2: 45659 | B2: DO-001 | C2: FG003 | D2: Tepung Terigu Protein Rendah | E2: PT Martinez-Murray | F2: Balikpapan | G2: 400 | H2: Pcs | I2: J&T | J2: =IFERROR(VLOOKUP(I2,'Kode Data'!$E$9:$F$13,2,0)&DATEVALUE(A2),"NA") -> NA | K2: NA | L2: Delivered | M2: 45667 | N2: =IFERROR(M2-A2,"NA") -> 8 | O2: =IF(AND(L2="Delivered",OR(AND(F2="Balikpapan",N2<=8),AND(F2="Bandung",N2<=4),AND(F2="Jakarta",N2<=4),AND(F2="Surabaya",N2<=1),AND(F2="Denpasar",N2<=5),AND(F2="Makassar",N2<=8),AND(F2="Medan",N2<=8),AND(F2="Pontianak",N2<=14),AND(F2="Semarang",N2<=2),AND(F2="Yogyakarta",N2<=3),)),"Tepat Waktu","Terlambat/Cancel") -> Tepat Waktu | Q2: Total Tepat Waktu | R2: =COUNTIF(O2:O107,"Tepat Waktu") -> 72
A3: 45659 | B3: DO-002 | C3: FG004 | D3: Tepung Terigu Khusus Roti | E3: PT Brown Group | F3: Surabaya | G3: 400 | H3: Pcs | I3: Armada Perusahaan | J3: =IFERROR(VLOOKUP(I3,'Kode Data'!$E$9:$F$13,2,0)&DATEVALUE(A3),"NA") -> NA | K3: AB7890IJ | L3: Delivered | M3: 45660 | N3: =IFERROR(M3-A3,"NA") -> 1 | O3: =IF(AND(L3="Delivered",OR(AND(F3="Balikpapan",N3<=8),AND(F3="Bandung",N3<=4),AND(F3="Jakarta",N3<=4),AND(F3="Surabaya",N3<=1),AND(F3="Denpasar",N3<=5),AND(F3="Makassar",N3<=8),AND(F3="Medan",N3<=8),AND(F3="Pontianak",N3<=14),AND(F3="Semarang",N3<=2),AND(F3="Yogyakarta",N3<=3),)),"Tepat Waktu","Terlambat/Cancel") -> Tepat Waktu | Q3: Total Terlambat/Cancel | R3: =COUNTIF(O2:O107,"Terlambat/Cancel") -> 34
A4: 45659 | B4: DO-003 | C4: FG005 | D4: Tepung Terigu Khusus Kue | E4: PT Roman, Johnson and Wright | F4: Bandung | G4: 300 | H4: Pcs | I4: Armada Perusahaan | J4: =IFERROR(VLOOKUP(I4,'Kode Data'!$E$9:$F$13,2,0)&DATEVALUE(A4),"NA") -> NA | K4: L1234AB | L4: Delivered | M4: 45663 | N4: =IFERROR(M4-A4,"NA") -> 4 | O4: =IF(AND(L4="Delivered",OR(AND(F4="Balikpapan",N4<=8),AND(F4="Bandung",N4<=4),AND(F4="Jakarta",N4<=4),AND(F4="Surabaya",N4<=1),AND(F4="Denpasar",N4<=5),AND(F4="Makassar",N4<=8),AND(F4="Medan",N4<=8),AND(F4="Pontianak",N4<=14),AND(F4="Semarang",N4<=2),AND(F4="Yogyakarta",N4<=3),)),"Tepat Waktu","Terlambat/Cancel") -> Tepat Waktu | Q4: Total PO | R4: =SUM(R2:R3) -> 106
A5: 45662 | B5: DO-004 | C5: FG003 | D5: Tepung Terigu Protein Rendah | E5: PT Hatfield-Pearson | F5: Yogyakarta | G5: 500 | H5: Pcs | I5: Armada Perusahaan | J5: =IFERROR(VLOOKUP(I5,'Kode Data'!$E$9:$F$13,2,0)&DATEVALUE(A5),"NA") -> NA | K5: L1234AB | L5: Delivered | M5: 45665 | N5: =IFERROR(M5-A5,"NA") -> 3 | O5: =IF(AND(L5="Delivered",OR(AND(F5="Balikpapan",N5<=8),AND(F5="Bandung",N5<=4),AND(F5="Jakarta",N5<=4),AND(F5="Surabaya",N5<=1),AND(F5="Denpasar",N5<=5),AND(F5="Makassar",N5<=8),AND(F5="Medan",N5<=8),AND(F5="Pontianak",N5<=14),AND(F5="Semarang",N5<=2),AND(F5="Yogyakarta",N5<=3),)),"Tepat Waktu","Terlambat/Cancel") -> Tepat Waktu
A6: 45662 | B6: DO-005 | C6: FG005 | D6: Tepung Terigu Khusus Kue | E6: PT Graves LLC | F6: Medan | G6: 400 | H6: Pcs | I6: POS Indonesia | J6: =IFERROR(VLOOKUP(I6,'Kode Data'!$E$9:$F$13,2,0)&DATEVALUE(A6),"NA") -> NA | K6: NA | L6: Delivered | M6: 45670 | N6: =IFERROR(M6-A6,"NA") -> 8 | O6: =IF(AND(L6="Delivered",OR(AND(F6="Balikpapan",N6<=8),AND(F6="Bandung",N6<=4),AND(F6="Jakarta",N6<=4),AND(F6="Surabaya",N6<=1),AND(F6="Denpasar",N6<=5),AND(F6="Makassar",N6<=8),AND(F6="Medan",N6<=8),AND(F6="Pontianak",N6<=14),AND(F6="Semarang",N6<=2),AND(F6="Yogyakarta",N6<=3),)),"Tepat Waktu","Terlambat/Cancel") -> Tepat Waktu
A7: 45665 | B7: DO-006 | C7: FG003 | D7: Tepung Terigu Protein Rendah | E7: PT Salas-Hodges | F7: Yogyakarta | G7: 350 | H7: Pcs | I7: Armada Perusahaan | J7: =IFERROR(VLOOKUP(I7,'Kode Data'!$E$9:$F$13,2,0)&DATEVALUE(A7),"NA") -> NA | K7: B9012EF | L7: Delivered | M7: 45668 | N7: =IFERROR(M7-A7,"NA") -> 3 | O7: =IF(AND(L7="Delivered",OR(AND(F7="Balikpapan",N7<=8),AND(F7="Bandung",N7<=4),AND(F7="Jakarta",N7<=4),AND(F7="Surabaya",N7<=1),AND(F7="Denpasar",N7<=5),AND(F7="Makassar",N7<=8),AND(F7="Medan",N7<=8),AND(F7="Pontianak",N7<=14),AND(F7="Semarang",N7<=2),AND(F7="Yogyakarta",N7<=3),)),"Tepat Waktu","Terlambat/Cancel") -> Tepat Waktu
A8: 45665 | B8: DO-007 | C8: FG005 | D8: Tepung Terigu Khusus Kue | E8: PT Woodard Ltd | F8: Denpasar | G8: 350 | H8: Pcs | I8: J&T | J8: =IFERROR(VLOOKUP(I8,'Kode Data'!$E$9:$F$13,2,0)&DATEVALUE(A8),"NA") -> NA | K8: NA | L8: Delivered | M8: 45670 | N8: =IFERROR(M8-A8,"NA") -> 5 | O8: =IF(AND(L8="Delivered",OR(AND(F8="Balikpapan",N8<=8),AND(F8="Bandung",N8<=4),AND(F8="Jakarta",N8<=4),AND(F8="Surabaya",N8<=1),AND(F8="Denpasar",N8<=5),AND(F8="Makassar",N8<=8),AND(F8="Medan",N8<=8),AND(F8="Pontianak",N8<=14),AND(F8="Semarang",N8<=2),AND(F8="Yogyakarta",N8<=3),)),"Tepat Waktu","Terlambat/Cancel") -> Tepat Waktu
A9: 45668 | B9: DO-008 | C9: FG003 | D9: Tepung Terigu Protein Rendah | E9: PT White, Hill and Pruitt | F9: Jakarta | G9: 400 | H9: Pcs | I9: Armada Perusahaan | J9: =IFERROR(VLOOKUP(I9,'Kode Data'!$E$9:$F$13,2,0)&DATEVALUE(A9),"NA") -> NA | K9: S5678CD | L9: Delivered | M9: 45673 | N9: =IFERROR(M9-A9,"NA") -> 5 | O9: =IF(AND(L9="Delivered",OR(AND(F9="Balikpapan",N9<=8),AND(F9="Bandung",N9<=4),AND(F9="Jakarta",N9<=4),AND(F9="Surabaya",N9<=1),AND(F9="Denpasar",N9<=5),AND(F9="Makassar",N9<=8),AND(F9="Medan",N9<=8),AND(F9="Pontianak",N9<=14),AND(F9="Semarang",N9<=2),AND(F9="Yogyakarta",N9<=3),)),"Tepat Waktu","Terlambat/Cancel") -> Terlambat/Cancel
A10: 45669 | B10: DO-009 | C10: FG001 | D10: Tepung Terigu Protein Tinggi | E10: PT Mckinney, Johnson and Campbell | F10: Bandung | G10: 400 | H10: Pcs | I10: Armada Perusahaan | J10: =IFERROR(VLOOKUP(I10,'Kode Data'!$E$9:$F$13,2,0)&DATEVALUE(A10),"NA") -> NA | K10: S5678CD | L10: Cancel | M10: NA | N10: =IFERROR(M10-A10,"NA") -> NA | O10: =IF(AND(L10="Delivered",OR(AND(F10="Balikpapan",N10<=8),AND(F10="Bandung",N10<=4),AND(F10="Jakarta",N10<=4),AND(F10="Surabaya",N10<=1),AND(F10="Denpasar",N10<=5),AND(F10="Makassar",N10<=8),AND(F10="Medan",N10<=8),AND(F10="Pontianak",N10<=14),AND(F10="Semarang",N10<=2),AND(F10="Yogyakarta",N10<=3),)),"Tepat Waktu","Terlambat/Cancel") -> Terlambat/Cancel
A11: 45669 | B11: DO-010 | C11: FG002 | D11: Tepung Terigu Serbaguna | E11: PT Bailey-Jimenez | F11: Surabaya | G11: 400 | H11: Pcs | I11: Armada Perusahaan | J11: =IFERROR(VLOOKUP(I11,'Kode Data'!$E$9:$F$13,2,0)&DATEVALUE(A11),"NA") -> NA | K11: W3456GH | L11: Delivered | M11: 45670 | N11: =IFERROR(M11-A11,"NA") -> 1 | O11: =IF(AND(L11="Delivered",OR(AND(F11="Balikpapan",N11<=8),AND(F11="Bandung",N11<=4),AND(F11="Jakarta",N11<=4),AND(F11="Surabaya",N11<=1),AND(F11="Denpasar",N11<=5),AND(F11="Makassar",N11<=8),AND(F11="Medan",N11<=8),AND(F11="Pontianak",N11<=14),AND(F11="Semarang",N11<=2),AND(F11="Yogyakarta",N11<=3),)),"Tepat Waktu","Terlambat/Cancel") -> Tepat Waktu
A12: 45669 | B12: DO-011 | C12: FG005 | D12: Tepung Terigu Khusus Kue | E12: PT Sanchez-Brown | F12: Surabaya | G12: 450 | H12: Pcs | I12: Armada Perusahaan | J12: =IFERROR(VLOOKUP(I12,'Kode Data'!$E$9:$F$13,2,0)&DATEVALUE(A12),"NA") -> NA | K12: B9012EF | L12: Delivered | M12: 45670 | N12: =IFERROR(M12-A12,"NA") -> 1 | O12: =IF(AND(L12="Delivered",OR(AND(F12="Balikpapan",N12<=8),AND(F12="Bandung",N12<=4),AND(F12="Jakarta",N12<=4),AND(F12="Surabaya",N12<=1),AND(F12="Denpasar",N12<=5),AND(F12="Makassar",N12<=8),AND(F12="Medan",N12<=8),AND(F12="Pontianak",N12<=14),AND(F12="Semarang",N12<=2),AND(F12="Yogyakarta",N12<=3),)),"Tepat Waktu","Terlambat/Cancel") -> Tepat Waktu
A13: 45684 | B13: DO-012 | C13: FG001 | D13: Tepung Terigu Protein Tinggi | E13: PT Johnson-Moreno | F13: Bandung | G13: 500 | H13: Pcs | I13: Armada Perusahaan | J13: =IFERROR(VLOOKUP(I13,'Kode Data'!$E$9:$F$13,2,0)&DATEVALUE(A13),"NA") -> NA | K13: AB7890IJ | L13: Delivered | M13: 45689 | N13: =IFERROR(M13-A13,"NA") -> 5 | O13: =IF(AND(L13="Delivered",OR(AND(F13="Balikpapan",N13<=8),AND(F13="Bandung",N13<=4),AND(F13="Jakarta",N13<=4),AND(F13="Surabaya",N13<=1),AND(F13="Denpasar",N13<=5),AND(F13="Makassar",N13<=8),AND(F13="Medan",N13<=8),AND(F13="Pontianak",N13<=14),AND(F13="Semarang",N13<=2),AND(F13="Yogyakarta",N13<=3),)),"Tepat Waktu","Terlambat/Cancel") -> Terlambat/Cancel
A14: 45684 | B14: DO-013 | C14: FG002 | D14: Tepung Terigu Serbaguna | E14: PT Hamilton Ltd | F14: Denpasar | G14: 350 | H14: Pcs | I14: SiCepat | J14: =IFERROR(VLOOKUP(I14,'Kode Data'!$E$9:$F$13,2,0)&DATEVALUE(A14),"NA") -> NA | K14: NA | L14: Delivered | M14: 45689 | N14: =IFERROR(M14-A14,"NA") -> 5 | O14: =IF(AND(L14="Delivered",OR(AND(F14="Balikpapan",N14<=8),AND(F14="Bandung",N14<=4),AND(F14="Jakarta",N14<=4),AND(F14="Surabaya",N14<=1),AND(F14="Denpasar",N14<=5),AND(F14="Makassar",N14<=8),AND(F14="Medan",N14<=8),AND(F14="Pontianak",N14<=14),AND(F14="Semarang",N14<=2),AND(F14="Yogyakarta",N14<=3),)),"Tepat Waktu","Terlambat/Cancel") -> Tepat Waktu
A15: 45693 | B15: DO-014 | C15: FG004 | D15: Tepung Terigu Khusus Roti | E15: PT Davis-Huynh | F15: Yogyakarta | G15: 500 | H15: Pcs | I15: Armada Perusahaan | J15: =IFERROR(VLOOKUP(I15,'Kode Data'!$E$9:$F$13,2,0)&DATEVALUE(A15),"NA") -> NA | K15: B9012EF | L15: Cancel | M15: NA | N15: =IFERROR(M15-A15,"NA") -> NA | O15: =IF(AND(L15="Delivered",OR(AND(F15="Balikpapan",N15<=8),AND(F15="Bandung",N15<=4),AND(F15="Jakarta",N15<=4),AND(F15="Surabaya",N15<=1),AND(F15="Denpasar",N15<=5),AND(F15="Makassar",N15<=8),AND(F15="Medan",N15<=8),AND(F15="Pontianak",N15<=14),AND(F15="Semarang",N15<=2),AND(F15="Yogyakarta",N15<=3),)),"Tepat Waktu","Terlambat/Cancel") -> Terlambat/Cancel
A16: 45699 | B16: DO-015 | C16: FG001 | D16: Tepung Terigu Protein Tinggi | E16: PT Taylor-Tran | F16: Medan | G16: 400 | H16: Pcs | I16: TIKI | J16: =IFERROR(VLOOKUP(I16,'Kode Data'!$E$9:$F$13,2,0)&DATEVALUE(A16),"NA") -> NA | K16: NA | L16: Delivered | M16: 45707 | N16: =IFERROR(M16-A16,"NA") -> 8 | O16: =IF(AND(L16="Delivered",OR(AND(F16="Balikpapan",N16<=8),AND(F16="Bandung",N16<=4),AND(F16="Jakarta",N16<=4),AND(F16="Surabaya",N16<=1),AND(F16="Denpasar",N16<=5),AND(F16="Makassar",N16<=8),AND(F16="Medan",N16<=8),AND(F16="Pontianak",N16<=14),AND(F16="Semarang",N16<=2),AND(F16="Yogyakarta",N16<=3),)),"Tepat Waktu","Terlambat/Cancel") -> Tepat Waktu
A17: 45699 | B17: DO-016 | C17: FG002 | D17: Tepung Terigu Serbaguna | E17: PT Barber-Cook | F17: Yogyakarta | G17: 500 | H17: Pcs | I17: Armada Perusahaan | J17: =IFERROR(VLOOKUP(I17,'Kode Data'!$E$9:$F$13,2,0)&DATEVALUE(A17),"NA") -> NA | K17: L1234AB | L17: Cancel | M17: NA | N17: =IFERROR(M17-A17,"NA") -> NA | O17: =IF(AND(L17="Delivered",OR(AND(F17="Balikpapan",N17<=8),AND(F17="Bandung",N17<=4),AND(F17="Jakarta",N17<=4),AND(F17="Surabaya",N17<=1),AND(F17="Denpasar",N17<=5),AND(F17="Makassar",N17<=8),AND(F17="Medan",N17<=8),AND(F17="Pontianak",N17<=14),AND(F17="Semarang",N17<=2),AND(F17="Yogyakarta",N17<=3),)),"Tepat Waktu","Terlambat/Cancel") -> Terlambat/Cancel
A18: 45702 | B18: DO-017 | C18: FG003 | D18: Tepung Terigu Protein Rendah | E18: PT Webb, Miller and Roth | F18: Bandung | G18: 450 | H18: Pcs | I18: Armada Perusahaan | J18: =IFERROR(VLOOKUP(I18,'Kode Data'!$E$9:$F$13,2,0)&DATEVALUE(A18),"NA") -> NA | K18: L1234AB | L18: Delivered | M18: 45706 | N18: =IFERROR(M18-A18,"NA") -> 4 | O18: =IF(AND(L18="Delivered",OR(AND(F18="Balikpapan",N18<=8),AND(F18="Bandung",N18<=4),AND(F18="Jakarta",N18<=4),AND(F18="Surabaya",N18<=1),AND(F18="Denpasar",N18<=5),AND(F18="Makassar",N18<=8),AND(F18="Medan",N18<=8),AND(F18="Pontianak",N18<=14),AND(F18="Semarang",N18<=2),AND(F18="Yogyakarta",N18<=3),)),"Tepat Waktu","Terlambat/Cancel") -> Tepat Waktu
A19: 45703 | B19: DO-018 | C19: FG005 | D19: Tepung Terigu Khusus Kue | E19: PT Williams, Oneill and Brown | F19: Jakarta | G19: 400 | H19: Pcs | I19: Armada Perusahaan | J19: =IFERROR(VLOOKUP(I19,'Kode Data'!$E$9:$F$13,2,0)&DATEVALUE(A19),"NA") -> NA | K19: S5678CD | L19: Delivered | M19: 45707 | N19: =IFERROR(M19-A19,"NA") -> 4 | O19: =IF(AND(L19="Delivered",OR(AND(F19="Balikpapan",N19<=8),AND(F19="Bandung",N19<=4),AND(F19="Jakarta",N19<=4),AND(F19="Surabaya",N19<=1),AND(F19="Denpasar",N19<=5),AND(F19="Makassar",N19<=8),AND(F19="Medan",N19<=8),AND(F19="Pontianak",N19<=14),AND(F19="Semarang",N19<=2),AND(F19="Yogyakarta",N19<=3),)),"Tepat Waktu","Terlambat/Cancel") -> Tepat Waktu
A20: 45706 | B20: DO-019 | C20: FG003 | D20: Tepung Terigu Protein Rendah | E20: PT Nielsen, Contreras and Miller | F20: Makassar | G20: 500 | H20: Pcs | I20: JNE | J20: =IFERROR(VLOOKUP(I20,'Kode Data'!$E$9:$F$13,2,0)&DATEVALUE(A20),"NA") -> NA | K20: NA | L20: Delivered | M20: 45714 | N20: =IFERROR(M20-A20,"NA") -> 8 | O20: =IF(AND(L20="Delivered",OR(AND(F20="Balikpapan",N20<=8),AND(F20="Bandung",N20<=4),AND(F20="Jakarta",N20<=4),AND(F20="Surabaya",N20<=1),AND(F20="Denpasar",N20<=5),AND(F20="Makassar",N20<=8),AND(F20="Medan",N20<=8),AND(F20="Pontianak",N20<=14),AND(F20="Semarang",N20<=2),AND(F20="Yogyakarta",N20<=3),)),"Tepat Waktu","Terlambat/Cancel") -> Tepat Waktu
A21: 45708 | B21: DO-020 | C21: FG003 | D21: Tepung Terigu Protein Rendah | E21: PT Schwartz LLC | F21: Surabaya | G21: 450 | H21: Pcs | I21: Armada Perusahaan | J21: =IFERROR(VLOOKUP(I21,'Kode Data'!$E$9:$F$13,2,0)&DATEVALUE(A21),"NA") -> NA | K21: B9012EF | L21: Delivered | M21: 45709 | N21: =IFERROR(M21-A21,"NA") -> 1 | O21: =IF(AND(L21="Delivered",OR(AND(F21="Balikpapan",N21<=8),AND(F21="Bandung",N21<=4),AND(F21="Jakarta",N21<=4),AND(F21="Surabaya",N21<=1),AND(F21="Denpasar",N21<=5),AND(F21="Makassar",N21<=8),AND(F21="Medan",N21<=8),AND(F21="Pontianak",N21<=14),AND(F21="Semarang",N21<=2),AND(F21="Yogyakarta",N21<=3),)),"Tepat Waktu","Terlambat/Cancel") -> Tepat Waktu
A22: 45712 | B22: DO-021 | C22: FG001 | D22: Tepung Terigu Protein Tinggi | E22: PT Tucker PLC | F22: Yogyakarta | G22: 600 | H22: Pcs | I22: Armada Perusahaan | J22: =IFERROR(VLOOKUP(I22,'Kode Data'!$E$9:$F$13,2,0)&DATEVALUE(A22),"NA") -> NA | K22: S5678CD | L22: Delivered | M22: 45715 | N22: =IFERROR(M22-A22,"NA") -> 3 | O22: =IF(AND(L22="Delivered",OR(AND(F22="Balikpapan",N22<=8),AND(F22="Bandung",N22<=4),AND(F22="Jakarta",N22<=4),AND(F22="Surabaya",N22<=1),AND(F22="Denpasar",N22<=5),AND(F22="Makassar",N22<=8),AND(F22="Medan",N22<=8),AND(F22="Pontianak",N22<=14),AND(F22="Semarang",N22<=2),AND(F22="Yogyakarta",N22<=3),)),"Tepat Waktu","Terlambat/Cancel") -> Tepat Waktu
A23: 45712 | B23: DO-022 | C23: FG002 | D23: Tepung Terigu Serbaguna | E23: PT Carroll, Nguyen and Nguyen | F23: Medan | G23: 400 | H23: Pcs | I23: POS Indonesia | J23: =IFERROR(VLOOKUP(I23,'Kode Data'!$E$9:$F$13,2,0)&DATEVALUE(A23),"NA") -> NA | K23: NA | L23: Delivered | M23: 45720 | N23: =IFERROR(M23-A23,"NA") -> 8 | O23: =IF(AND(L23="Delivered",OR(AND(F23="Balikpapan",N23<=8),AND(F23="Bandung",N23<=4),AND(F23="Jakarta",N23<=4),AND(F23="Surabaya",N23<=1),AND(F23="Denpasar",N23<=5),AND(F23="Makassar",N23<=8),AND(F23="Medan",N23<=8),AND(F23="Pontianak",N23<=14),AND(F23="Semarang",N23<=2),AND(F23="Yogyakarta",N23<=3),)),"Tepat Waktu","Terlambat/Cancel") -> Tepat Waktu
A24: 45725 | B24: DO-023 | C24: FG001 | D24: Tepung Terigu Protein Tinggi | E24: PT Hall, Johnson and Gomez | F24: Yogyakarta | G24: 500 | H24: Pcs | I24: Armada Perusahaan | J24: =IFERROR(VLOOKUP(I24,'Kode Data'!$E$9:$F$13,2,0)&DATEVALUE(A24),"NA") -> NA | K24: W3456GH | L24: Delivered | M24: 45730 | N24: =IFERROR(M24-A24,"NA") -> 5 | O24: =IF(AND(L24="Delivered",OR(AND(F24="Balikpapan",N24<=8),AND(F24="Bandung",N24<=4),AND(F24="Jakarta",N24<=4),AND(F24="Surabaya",N24<=1),AND(F24="Denpasar",N24<=5),AND(F24="Makassar",N24<=8),AND(F24="Medan",N24<=8),AND(F24="Pontianak",N24<=14),AND(F24="Semarang",N24<=2),AND(F24="Yogyakarta",N24<=3),)),"Tepat Waktu","Terlambat/Cancel") -> Terlambat/Cancel
A25: 45728 | B25: DO-024 | C25: FG004 | D25: Tepung Terigu Khusus Roti | E25: PT Brock-Rosario | F25: Medan | G25: 300 | H25: Pcs | I25: JNE | J25: =IFERROR(VLOOKUP(I25,'Kode Data'!$E$9:$F$13,2,0)&DATEVALUE(A25),"NA") -> NA | K25: NA | L25: Delivered | M25: 45736 | N25: =IFERROR(M25-A25,"NA") -> 8 | O25: =IF(AND(L25="Delivered",OR(AND(F25="Balikpapan",N25<=8),AND(F25="Bandung",N25<=4),AND(F25="Jakarta",N25<=4),AND(F25="Surabaya",N25<=1),AND(F25="Denpasar",N25<=5),AND(F25="Makassar",N25<=8),AND(F25="Medan",N25<=8),AND(F25="Pontianak",N25<=14),AND(F25="Semarang",N25<=2),AND(F25="Yogyakarta",N25<=3),)),"Tepat Waktu","Terlambat/Cancel") -> Tepat Waktu
A26: 45730 | B26: DO-025 | C26: FG002 | D26: Tepung Terigu Serbaguna | E26: PT Hunt PLC | F26: Medan | G26: 600 | H26: Pcs | I26: TIKI | J26: =IFERROR(VLOOKUP(I26,'Kode Data'!$E$9:$F$13,2,0)&DATEVALUE(A26),"NA") -> NA | K26: NA | L26: Delivered | M26: 45738 | N26: =IFERROR(M26-A26,"NA") -> 8 | O26: =IF(AND(L26="Delivered",OR(AND(F26="Balikpapan",N26<=8),AND(F26="Bandung",N26<=4),AND(F26="Jakarta",N26<=4),AND(F26="Surabaya",N26<=1),AND(F26="Denpasar",N26<=5),AND(F26="Makassar",N26<=8),AND(F26="Medan",N26<=8),AND(F26="Pontianak",N26<=14),AND(F26="Semarang",N26<=2),AND(F26="Yogyakarta",N26<=3),)),"Tepat Waktu","Terlambat/Cancel") -> Tepat Waktu
A27: 45734 | B27: DO-026 | C27: FG005 | D27: Tepung Terigu Khusus Kue | E27: PT Cline Group | F27: Balikpapan | G27: 500 | H27: Pcs | I27: JNE | J27: =IFERROR(VLOOKUP(I27,'Kode Data'!$E$9:$F$13,2,0)&DATEVALUE(A27),"NA") -> NA | K27: NA | L27: Delivered | M27: 45744 | N27: =IFERROR(M27-A27,"NA") -> 10 | O27: =IF(AND(L27="Delivered",OR(AND(F27="Balikpapan",N27<=8),AND(F27="Bandung",N27<=4),AND(F27="Jakarta",N27<=4),AND(F27="Surabaya",N27<=1),AND(F27="Denpasar",N27<=5),AND(F27="Makassar",N27<=8),AND(F27="Medan",N27<=8),AND(F27="Pontianak",N27<=14),AND(F27="Semarang",N27<=2),AND(F27="Yogyakarta",N27<=3),)),"Tepat Waktu","Terlambat/Cancel") -> Terlambat/Cancel
A28: 45739 | B28: DO-027 | C28: FG001 | D28: Tepung Terigu Protein Tinggi | E28: PT Gutierrez Ltd | F28: Surabaya | G28: 700 | H28: Pcs | I28: Armada Perusahaan | J28: =IFERROR(VLOOKUP(I28,'Kode Data'!$E$9:$F$13,2,0)&DATEVALUE(A28),"NA") -> NA | K28: B9012EF | L28: Cancel | M28: NA | N28: =IFERROR(M28-A28,"NA") -> NA | O28: =IF(AND(L28="Delivered",OR(AND(F28="Balikpapan",N28<=8),AND(F28="Bandung",N28<=4),AND(F28="Jakarta",N28<=4),AND(F28="Surabaya",N28<=1),AND(F28="Denpasar",N28<=5),AND(F28="Makassar",N28<=8),AND(F28="Medan",N28<=8),AND(F28="Pontianak",N28<=14),AND(F28="Semarang",N28<=2),AND(F28="Yogyakarta",N28<=3),)),"Tepat Waktu","Terlambat/Cancel") -> Terlambat/Cancel
A29: 45739 | B29: DO-028 | C29: FG003 | D29: Tepung Terigu Protein Rendah | E29: PT Myers-Garcia | F29: Pontianak | G29: 400 | H29: Pcs | I29: TIKI | J29: =IFERROR(VLOOKUP(I29,'Kode Data'!$E$9:$F$13,2,0)&DATEVALUE(A29),"NA") -> NA | K29: NA | L29: Delivered | M29: 45753 | N29: =IFERROR(M29-A29,"NA") -> 14 | O29: =IF(AND(L29="Delivered",OR(AND(F29="Balikpapan",N29<=8),AND(F29="Bandung",N29<=4),AND(F29="Jakarta",N29<=4),AND(F29="Surabaya",N29<=1),AND(F29="Denpasar",N29<=5),AND(F29="Makassar",N29<=8),AND(F29="Medan",N29<=8),AND(F29="Pontianak",N29<=14),AND(F29="Semarang",N29<=2),AND(F29="Yogyakarta",N29<=3),)),"Tepat Waktu","Terlambat/Cancel") -> Tepat Waktu
A30: 45742 | B30: DO-029 | C30: FG003 | D30: Tepung Terigu Protein Rendah | E30: PT Logan Group | F30: Surabaya | G30: 500 | H30: Pcs | I30: Armada Perusahaan | J30: =IFERROR(VLOOKUP(I30,'Kode Data'!$E$9:$F$13,2,0)&DATEVALUE(A30),"NA") -> NA | K30: B9012EF | L30: Delivered | M30: 45743 | N30: =IFERROR(M30-A30,"NA") -> 1 | O30: =IF(AND(L30="Delivered",OR(AND(F30="Balikpapan",N30<=8),AND(F30="Bandung",N30<=4),AND(F30="Jakarta",N30<=4),AND(F30="Surabaya",N30<=1),AND(F30="Denpasar",N30<=5),AND(F30="Makassar",N30<=8),AND(F30="Medan",N30<=8),AND(F30="Pontianak",N30<=14),AND(F30="Semarang",N30<=2),AND(F30="Yogyakarta",N30<=3),)),"Tepat Waktu","Terlambat/Cancel") -> Tepat Waktu
A31: 45745 | B31: DO-030 | C31: FG003 | D31: Tepung Terigu Protein Rendah | E31: PT Gibson-Webb | F31: Yogyakarta | G31: 550 | H31: Pcs | I31: Armada Perusahaan | J31: =IFERROR(VLOOKUP(I31,'Kode Data'!$E$9:$F$13,2,0)&DATEVALUE(A31),"NA") -> NA | K31: AB7890IJ | L31: Delivered | M31: 45748 | N31: =IFERROR(M31-A31,"NA") -> 3 | O31: =IF(AND(L31="Delivered",OR(AND(F31="Balikpapan",N31<=8),AND(F31="Bandung",N31<=4),AND(F31="Jakarta",N31<=4),AND(F31="Surabaya",N31<=1),AND(F31="Denpasar",N31<=5),AND(F31="Makassar",N31<=8),AND(F31="Medan",N31<=8),AND(F31="Pontianak",N31<=14),AND(F31="Semarang",N31<=2),AND(F31="Yogyakarta",N31<=3),)),"Tepat Waktu","Terlambat/Cancel") -> Tepat Waktu
A32: 45746 | B32: DO-031 | C32: FG002 | D32: Tepung Terigu Serbaguna | E32: PT Watkins, Day and Wolf | F32: Semarang | G32: 500 | H32: Pcs | I32: Armada Perusahaan | J32: =IFERROR(VLOOKUP(I32,'Kode Data'!$E$9:$F$13,2,0)&DATEVALUE(A32),"NA") -> NA | K32: AB7890IJ | L32: Cancel | M32: NA | N32: =IFERROR(M32-A32,"NA") -> NA | O32: =IF(AND(L32="Delivered",OR(AND(F32="Balikpapan",N32<=8),AND(F32="Bandung",N32<=4),AND(F32="Jakarta",N32<=4),AND(F32="Surabaya",N32<=1),AND(F32="Denpasar",N32<=5),AND(F32="Makassar",N32<=8),AND(F32="Medan",N32<=8),AND(F32="Pontianak",N32<=14),AND(F32="Semarang",N32<=2),AND(F32="Yogyakarta",N32<=3),)),"Tepat Waktu","Terlambat/Cancel") -> Terlambat/Cancel
A33: 45748 | B33: DO-032 | C33: FG003 | D33: Tepung Terigu Protein Rendah | E33: PT Lin-Escobar | F33: Bandung | G33: 500 | H33: Pcs | I33: Armada Perusahaan | J33: =IFERROR(VLOOKUP(I33,'Kode Data'!$E$9:$F$13,2,0)&DATEVALUE(A33),"NA") -> NA | K33: W3456GH | L33: Delivered | M33: 45752 | N33: =IFERROR(M33-A33,"NA") -> 4 | O33: =IF(AND(L33="Delivered",OR(AND(F33="Balikpapan",N33<=8),AND(F33="Bandung",N33<=4),AND(F33="Jakarta",N33<=4),AND(F33="Surabaya",N33<=1),AND(F33="Denpasar",N33<=5),AND(F33="Makassar",N33<=8),AND(F33="Medan",N33<=8),AND(F33="Pontianak",N33<=14),AND(F33="Semarang",N33<=2),AND(F33="Yogyakarta",N33<=3),)),"Tepat Waktu","Terlambat/Cancel") -> Tepat Waktu
A34: 45751 | B34: DO-033 | C34: FG003 | D34: Tepung Terigu Protein Rendah | E34: PT Lawrence-Burke | F34: Bandung | G34: 550 | H34: Pcs | I34: Armada Perusahaan | J34: =IFERROR(VLOOKUP(I34,'Kode Data'!$E$9:$F$13,2,0)&DATEVALUE(A34),"NA") -> NA | K34: B9012EF | L34: Delivered | M34: 45755 | N34: =IFERROR(M34-A34,"NA") -> 4 | O34: =IF(AND(L34="Delivered",OR(AND(F34="Balikpapan",N34<=8),AND(F34="Bandung",N34<=4),AND(F34="Jakarta",N34<=4),AND(F34="Surabaya",N34<=1),AND(F34="Denpasar",N34<=5),AND(F34="Makassar",N34<=8),AND(F34="Medan",N34<=8),AND(F34="Pontianak",N34<=14),AND(F34="Semarang",N34<=2),AND(F34="Yogyakarta",N34<=3),)),"Tepat Waktu","Terlambat/Cancel") -> Tepat Waktu
A35: 45754 | B35: DO-034 | C35: FG003 | D35: Tepung Terigu Protein Rendah | E35: PT Munoz-Wilcox | F35: Semarang | G35: 500 | H35: Pcs | I35: Armada Perusahaan | J35: =IFERROR(VLOOKUP(I35,'Kode Data'!$E$9:$F$13,2,0)&DATEVALUE(A35),"NA") -> NA | K35: AB7890IJ | L35: Delivered | M35: 45757 | N35: =IFERROR(M35-A35,"NA") -> 3 | O35: =IF(AND(L35="Delivered",OR(AND(F35="Balikpapan",N35<=8),AND(F35="Bandung",N35<=4),AND(F35="Jakarta",N35<=4),AND(F35="Surabaya",N35<=1),AND(F35="Denpasar",N35<=5),AND(F35="Makassar",N35<=8),AND(F35="Medan",N35<=8),AND(F35="Pontianak",N35<=14),AND(F35="Semarang",N35<=2),AND(F35="Yogyakarta",N35<=3),)),"Tepat Waktu","Terlambat/Cancel") -> Terlambat/Cancel
A36: 45756 | B36: DO-035 | C36: FG002 | D36: Tepung Terigu Serbaguna | E36: PT Russo Inc | F36: Bandung | G36: 450 | H36: Pcs | I36: Armada Perusahaan | J36: =IFERROR(VLOOKUP(I36,'Kode Data'!$E$9:$F$13,2,0)&DATEVALUE(A36),"NA") -> NA | K36: S5678CD | L36: Delivered | M36: 45760 | N36: =IFERROR(M36-A36,"NA") -> 4 | O36: =IF(AND(L36="Delivered",OR(AND(F36="Balikpapan",N36<=8),AND(F36="Bandung",N36<=4),AND(F36="Jakarta",N36<=4),AND(F36="Surabaya",N36<=1),AND(F36="Denpasar",N36<=5),AND(F36="Makassar",N36<=8),AND(F36="Medan",N36<=8),AND(F36="Pontianak",N36<=14),AND(F36="Semarang",N36<=2),AND(F36="Yogyakarta",N36<=3),)),"Tepat Waktu","Terlambat/Cancel") -> Tepat Waktu
A37: 45757 | B37: DO-036 | C37: FG001 | D37: Tepung Terigu Protein Tinggi | E37: PT Beard, Johnson and Walsh | F37: Yogyakarta | G37: 400 | H37: Pcs | I37: Armada Perusahaan | J37: =IFERROR(VLOOKUP(I37,'Kode Data'!$E$9:$F$13,2,0)&DATEVALUE(A37),"NA") -> NA | K37: AB7890IJ | L37: Delivered | M37: 45760 | N37: =IFERROR(M37-A37,"NA") -> 3 | O37: =IF(AND(L37="Delivered",OR(AND(F37="Balikpapan",N37<=8),AND(F37="Bandung",N37<=4),AND(F37="Jakarta",N37<=4),AND(F37="Surabaya",N37<=1),AND(F37="Denpasar",N37<=5),AND(F37="Makassar",N37<=8),AND(F37="Medan",N37<=8),AND(F37="Pontianak",N37<=14),AND(F37="Semarang",N37<=2),AND(F37="Yogyakarta",N37<=3),)),"Tepat Waktu","Terlambat/Cancel") -> Tepat Waktu
A38: 45757 | B38: DO-037 | C38: FG003 | D38: Tepung Terigu Protein Rendah | E38: PT Jordan Inc | F38: Yogyakarta | G38: 550 | H38: Pcs | I38: Armada Perusahaan | J38: =IFERROR(VLOOKUP(I38,'Kode Data'!$E$9:$F$13,2,0)&DATEVALUE(A38),"NA") -> NA | K38: W3456GH | L38: Delivered | M38: 45760 | N38: =IFERROR(M38-A38,"NA") -> 3 | O38: =IF(AND(L38="Delivered",OR(AND(F38="Balikpapan",N38<=8),AND(F38="Bandung",N38<=4),AND(F38="Jakarta",N38<=4),AND(F38="Surabaya",N38<=1),AND(F38="Denpasar",N38<=5),AND(F38="Makassar",N38<=8),AND(F38="Medan",N38<=8),AND(F38="Pontianak",N38<=14),AND(F38="Semarang",N38<=2),AND(F38="Yogyakarta",N38<=3),)),"Tepat Waktu","Terlambat/Cancel") -> Tepat Waktu
A39: 45760 | B39: DO-038 | C39: FG003 | D39: Tepung Terigu Protein Rendah | E39: PT Hill-Baker | F39: Yogyakarta | G39: 600 | H39: Pcs | I39: Armada Perusahaan | J39: =IFERROR(VLOOKUP(I39,'Kode Data'!$E$9:$F$13,2,0)&DATEVALUE(A39),"NA") -> NA | K39: S5678CD | L39: Delivered | M39: 45763 | N39: =IFERROR(M39-A39,"NA") -> 3 | O39: =IF(AND(L39="Delivered",OR(AND(F39="Balikpapan",N39<=8),AND(F39="Bandung",N39<=4),AND(F39="Jakarta",N39<=4),AND(F39="Surabaya",N39<=1),AND(F39="Denpasar",N39<=5),AND(F39="Makassar",N39<=8),AND(F39="Medan",N39<=8),AND(F39="Pontianak",N39<=14),AND(F39="Semarang",N39<=2),AND(F39="Yogyakarta",N39<=3),)),"Tepat Waktu","Terlambat/Cancel") -> Tepat Waktu
A40: 45764 | B40: DO-039 | C40: FG004 | D40: Tepung Terigu Khusus Roti | E40: PT Parker, Flores and Jones | F40: Makassar | G40: 400 | H40: Pcs | I40: POS Indonesia | J40: =IFERROR(VLOOKUP(I40,'Kode Data'!$E$9:$F$13,2,0)&DATEVALUE(A40),"NA") -> NA | K40: NA | L40: Delivered | M40: 45772 | N40: =IFERROR(M40-A40,"NA") -> 8 | O40: =IF(AND(L40="Delivered",OR(AND(F40="Balikpapan",N40<=8),AND(F40="Bandung",N40<=4),AND(F40="Jakarta",N40<=4),AND(F40="Surabaya",N40<=1),AND(F40="Denpasar",N40<=5),AND(F40="Makassar",N40<=8),AND(F40="Medan",N40<=8),AND(F40="Pontianak",N40<=14),AND(F40="Semarang",N40<=2),AND(F40="Yogyakarta",N40<=3),)),"Tepat Waktu","Terlambat/Cancel") -> Tepat Waktu
...

Sheet Pivot Tabel
B2: Barang | C2: Stok Akhir Barang | E2: Row Labels | F2: Sum of Barang Masuk | H2: Row Labels | I2: Sum of Barang Keluar | K2: Row Labels | L2: Sum of Barang Keluar | N2: Row Labels | O2: Count of No Delivery Order | Q2: Sum of Barang Keluar | R2: Column Labels
B3: Enzim Baking | C3: 280 | E3: PT Sumber Pangan | F3: 29970 | H3: PT Archer-Cortez | I3: 700 | K3: Balikpapan | L3: 2400 | N3: Armada Perusahaan | O3: 66 | Q3: Row Labels | R3: Tepung Terigu Khusus Kue | S3: Tepung Terigu Khusus Roti | T3: Tepung Terigu Protein Rendah | U3: Tepung Terigu Protein Tinggi | V3: Tepung Terigu Serbaguna | W3: Grand Total
B4: Pallet Kayu | C4: 350 | E4: PT Agro Makmur | F4: 28880 | H4: PT Bailey-Jimenez | I4: 400 | K4: Bandung | L4: 11250 | N4: J&T | O4: 3 | Q4: Jan | R4: 1500 | S4: 400 | T4: 1650 | U4: 900 | V4: 750 | W4: 5200
B5: Improver Tepung | C5: 410 | E5: PT Pangan Nusantara | F5: 14920 | H5: PT Barber-Cook | I5: 500 | K5: Denpasar | L5: 2450 | N5: JNE | O5: 9 | Q5: Feb | R5: 400 | S5: 500 | T5: 1400 | U5: 1000 | V5: 900 | W5: 4200
B6: Calcium Propionate | C6: 730 | E6: PT Pangan Jaya | F6: 13900 | H6: PT Beard, Johnson and Walsh | I6: 400 | K6: Jakarta | L6: 2100 | N6: POS Indonesia | O6: 11 | Q6: Mar | R6: 500 | S6: 300 | T6: 1450 | U6: 1200 | V6: 1100 | W6: 4550
B7: Tepung Premix | C7: 880 | E7: PT Plastik Nusantara | F7: 11700 | H7: PT Brock-Rosario | I7: 300 | K7: Makassar | L7: 7450 | N7: SiCepat | O7: 8 | Q7: Apr | R7: 850 | S7: 400 | T7: 2700 | U7: 900 | V7: 850 | W7: 5700
B8: Vitamin Fortifikasi | C8: 940 | E8: PT Karton Indonesia | F8: 11200 | H8: PT Brown Group | I8: 400 | K8: Medan | L8: 6900 | N8: TIKI | O8: 9 | Q8: May | R8: 500 | S8: 350 | T8: 1800 | U8: 1300 | V8: 1100 | W8: 5050
B9: Gandum Durum | C9: 1640 | E9: PT Plastik Indo | F9: 8400 | H9: PT Brown, Howard and Robbins | I9: 500 | K9: Pontianak | L9: 1500 | N9: Grand Total | O9: 106 | Q9: Jun | R9: 450 | S9: 450 | T9: 1800 | U9: 1100 | V9: 1300 | W9: 5100
B10: Tepung Terigu Khusus Roti | C10: 1850 | E10: PT Karton Nusantara | F10: 8100 | H10: PT Byrd Inc | I10: 650 | K10: Semarang | L10: 3250 | Q10: Jul | R10: 950 | S10: 300 | T10: 1200 | U10: 1200 | V10: 1100 | W10: 4750
B11: Tepung Terigu Protein Tinggi | C11: 2100 | E11: PT Plastik Sejahtera | F11: 7700 | H11: PT Carr Group | I11: 1000 | K11: Surabaya | L11: 5500 | N11: Row Labels | O11: Count of No Delivery Order | Q11: Aug | R11: 500 | T11: 600 | U11: 1300 | V11: 1500 | W11: 3900
B12: Label Produk | C12: 2200 | E12: PT Karton Jaya | F12: 6500 | H12: PT Carroll, Nguyen and Nguyen | I12: 400 | K12: Yogyakarta | L12: 12750 | N12: Tepat Waktu | O12: 72 | Q12: Sep | R12: 950 | S12: 450 | U12: 1100 | V12: 1300 | W12: 3800
B13: Germ Gandum | C13: 2410 | E13: PT Kemasan Jaya | F13: 6050 | H13: PT Castillo, Morales and Lang | I13: 600 | K13: Grand Total | L13: 55550 | N13: Terlambat/Cancel | O13: 34 | Q13: Oct | R13: 950 | U13: 1200 | V13: 1700 | W13: 3850
B14: Tepung Terigu Protein Rendah | C14: 2800 | E14: PT Distributor B | F14: 5300 | H14: PT Cervantes-Estrada | I14: 600 | N14: Grand Total | O14: 106 | Q14: Nov | R14: 950 | S14: 350 | U14: 1300 | V14: 1300 | W14: 3900
B15: Gandum Soft Wheat | C15: 2800 | E15: PT Distributor A | F15: 5100 | H15: PT Cline Group | I15: 500 | Q15: Dec | R15: 2350 | S15: 400 | U15: 1100 | V15: 1700 | W15: 5550
B16: Bran Gandum | C16: 2900 | E16: PT Distributor C | F16: 5000 | H16: PT Conley-Davis | I16: 450 | N16: Tepat Waktu | O16: ='Tracking Distribusi Barang'!R2/'Tracking Distribusi Barang'!R4*100% -> 0.67924528 | Q16: Grand Total | R16: 10850 | S16: 3900 | T16: 12600 | U16: 13600 | V16: 14600 | W16: 55550
B17: Tepung Terigu Serbaguna | C17: 3100 | E17: PT Mega Flour | F17: 4550 | H17: PT Cross PLC | I17: 600 | N17: Terlambar/Cancel | O17: ='Tracking Distribusi Barang'!R3/'Tracking Distribusi Barang'!R4*100% -> 0.32075472
B18: Gandum Hard Wheat | C18: 3700 | E18: PT Baker Indonesia | F18: 4450 | H18: PT Cruz Ltd | I18: 700
B19: Tepung Terigu Khusus Kue | C19: 3750 | E19: PT Labelindo | F19: 4200 | H19: PT Cummings-Stevens | I19: 600
B20: Karung Kemasan 25 Kg | C20: 5520 | E20: PT Label Makmur | F20: 4200 | H20: PT David-Smith | I20: 600
B21: Plastik Kemasan 500 gr | C21: 9350 | E21: PT Packaging Indo | F21: 3100 | H21: PT Davis Ltd | I21: 400
B22: Karton Box | C22: 14450 | E22: PT Sumber Bumi | F22: 3050 | H22: PT Davis-Huynh | I22: 500
B23: Plastik Kemasan 1 Kg | C23: 17100 | E23: PT Label Indo Jaya | F23: 2400 | H23: PT Davis-Walter | I23: 600
B24: Grand Total | C24: 79260 | E24: PT Nutri Pangan | F24: 1670 | H24: PT Dawson-Freeman | I24: 600
E25: PT Indo Additive | F25: 1210 | H25: PT Dennis Inc | I25: 500
E26: PT FoodChem Indonesia | F26: 1160 | H26: PT Dorsey and Sons | I26: 450
E27: PT Forti Pangan | F27: 1010 | H27: PT Duncan Group | I27: 600
E28: PT Nutri Indo | F28: 980 | H28: PT Evans-Floyd | I28: 300
E29: PT Bio Enzim | F29: 950 | H29: PT Fernandez-Freeman | I29: 450
E30: PT Enzim Global | F30: 845 | H30: PT Ferrell, Hughes and Reed | I30: 500
E31: PT Bio Enzim Nusantara | F31: 820 | H31: PT Gay, Meza and Jackson | I31: 600
E32: PT Food Additive Indonesia | F32: 820 | H32: PT Gibson-Webb | I32: 550
E33: PT Pallet Nusantara | F33: 450 | H33: PT Graves LLC | I33: 400
E34: PT Kayu Abadi | F34: 450 | H34: PT Gutierrez Ltd | I34: 700
E35: PT Baking Solution | F35: 380 | H35: PT Gutierrez-Olson | I35: 700
E36: PT Kayu Mandiri | F36: 380 | H36: PT Hall Group | I36: 450
... E38: Grand Total | F38: 200155 | H38: PT Hall, Johnson and Gomez | I38: 500
H39: PT Hamilton Ltd | I39: 350
H40: PT Harper Ltd | I40: 1300
H41: PT Hatfield-Pearson | I41: 500
H42: PT Hill-Baker | I42: 600
...
